Workbook

Sheet 📊 Master Summary
A1: CASH FLOW OFFICE | 13-Week Master Cash Flow Summary — All Jobs
A2: Company: | D2: Owner / PM: | G2: Period Start: | J2: Report Date:
A3: 🔴 Company Red Zone Threshold: | B3: 10000 | C3: ← Minimum combined cash across all jobs. Set this at the company level — typically higher than any single job threshold.
A5: JOB / METRIC | C5: 13-WK TOTAL | D5: Week 1 | E5: Week 2 | F5: Week 3 | G5: Week 4 | H5: Week 5 | I5: Week 6 | J5: Week 7 | K5: Week 8 | L5: Week 9 | M5: Week 10 | N5: Week 11 | O5: Week 12 | P5: Week 13
A6: Week Starting Date → | D6: ='📋 Job 1'!D6 -> 0 | E6: ='📋 Job 1'!E6 -> 0 | F6: ='📋 Job 1'!F6 -> 0 | G6: ='📋 Job 1'!G6 -> 0 | H6: ='📋 Job 1'!H6 -> 0 | I6: ='📋 Job 1'!I6 -> 0 | J6: ='📋 Job 1'!J6 -> 0 | K6: ='📋 Job 1'!K6 -> 0 | ... P6: ='📋 Job 1'!P6 -> 0
A8: ▼ WEEKLY CASH FLOW BY JOB
A9: Job 1
A10: Total Inflows | C10: =SUM('📋 Job 1'!D13:P13) -> 0 | D10: ='📋 Job 1'!D13 -> 0 | E10: ='📋 Job 1'!E13 -> 0 | F10: ='📋 Job 1'!F13 -> 0 | G10: ='📋 Job 1'!G13 -> 0 | H10: ='📋 Job 1'!H13 -> 0 | I10: ='📋 Job 1'!I13 -> 0 | J10: ='📋 Job 1'!J13 -> 0 | K10: ='📋 Job 1'!K13 -> 0 | ... P10: ='📋 Job 1'!P13 -> 0
A11: Total Outflows | C11: =SUM('📋 Job 1'!D24:P24) -> 0 | D11: ='📋 Job 1'!D24 -> 0 | E11: ='📋 Job 1'!E24 -> 0 | F11: ='📋 Job 1'!F24 -> 0 | G11: ='📋 Job 1'!G24 -> 0 | H11: ='📋 Job 1'!H24 -> 0 | I11: ='📋 Job 1'!I24 -> 0 | J11: ='📋 Job 1'!J24 -> 0 | K11: ='📋 Job 1'!K24 -> 0 | ... P11: ='📋 Job 1'!P24 -> 0
A12: Net Cash Flow | C12: =SUM('📋 Job 1'!D26:P26) -> 0 | D12: ='📋 Job 1'!D26 -> 0 | E12: ='📋 Job 1'!E26 -> 0 | F12: ='📋 Job 1'!F26 -> 0 | G12: ='📋 Job 1'!G26 -> 0 | H12: ='📋 Job 1'!H26 -> 0 | I12: ='📋 Job 1'!I26 -> 0 | J12: ='📋 Job 1'!J26 -> 0 | K12: ='📋 Job 1'!K26 -> 0 | ... P12: ='📋 Job 1'!P26 -> 0
A13: Ending Cash Balance | C13: ='📋 Job 1'!P27 -> 0 | D13: ='📋 Job 1'!D27 -> 0 | E13: ='📋 Job 1'!E27 -> 0 | F13: ='📋 Job 1'!F27 -> 0 | G13: ='📋 Job 1'!G27 -> 0 | H13: ='📋 Job 1'!H27 -> 0 | I13: ='📋 Job 1'!I27 -> 0 | J13: ='📋 Job 1'!J27 -> 0 | K13: ='📋 Job 1'!K27 -> 0 | ... P13: ='📋 Job 1'!P27 -> 0
A15: Job 2
A16: Total Inflows | C16: =SUM('📋 Job 2'!D13:P13) -> 0 | D16: ='📋 Job 2'!D13 -> 0 | E16: ='📋 Job 2'!E13 -> 0 | F16: ='📋 Job 2'!F13 -> 0 | G16: ='📋 Job 2'!G13 -> 0 | H16: ='📋 Job 2'!H13 -> 0 | I16: ='📋 Job 2'!I13 -> 0 | J16: ='📋 Job 2'!J13 -> 0 | K16: ='📋 Job 2'!K13 -> 0 | ... P16: ='📋 Job 2'!P13 -> 0
A17: Total Outflows | C17: =SUM('📋 Job 2'!D24:P24) -> 0 | D17: ='📋 Job 2'!D24 -> 0 | E17: ='📋 Job 2'!E24 -> 0 | F17: ='📋 Job 2'!F24 -> 0 | G17: ='📋 Job 2'!G24 -> 0 | H17: ='📋 Job 2'!H24 -> 0 | I17: ='📋 Job 2'!I24 -> 0 | J17: ='📋 Job 2'!J24 -> 0 | K17: ='📋 Job 2'!K24 -> 0 | ... P17: ='📋 Job 2'!P24 -> 0
A18: Net Cash Flow | C18: =SUM('📋 Job 2'!D26:P26) -> 0 | D18: ='📋 Job 2'!D26 -> 0 | E18: ='📋 Job 2'!E26 -> 0 | F18: ='📋 Job 2'!F26 -> 0 | G18: ='📋 Job 2'!G26 -> 0 | H18: ='📋 Job 2'!H26 -> 0 | I18: ='📋 Job 2'!I26 -> 0 | J18: ='📋 Job 2'!J26 -> 0 | K18: ='📋 Job 2'!K26 -> 0 | ... P18: ='📋 Job 2'!P26 -> 0
A19: Ending Cash Balance | C19: ='📋 Job 2'!P27 -> 0 | D19: ='📋 Job 2'!D27 -> 0 | E19: ='📋 Job 2'!E27 -> 0 | F19: ='📋 Job 2'!F27 -> 0 | G19: ='📋 Job 2'!G27 -> 0 | H19: ='📋 Job 2'!H27 -> 0 | I19: ='📋 Job 2'!I27 -> 0 | J19: ='📋 Job 2'!J27 -> 0 | K19: ='📋 Job 2'!K27 -> 0 | ... P19: ='📋 Job 2'!P27 -> 0
A21: Job 3
A22: Total Inflows | C22: =SUM('📋 Job 3'!D13:P13) -> 0 | D22: ='📋 Job 3'!D13 -> 0 | E22: ='📋 Job 3'!E13 -> 0 | F22: ='📋 Job 3'!F13 -> 0 | G22: ='📋 Job 3'!G13 -> 0 | H22: ='📋 Job 3'!H13 -> 0 | I22: ='📋 Job 3'!I13 -> 0 | J22: ='📋 Job 3'!J13 -> 0 | K22: ='📋 Job 3'!K13 -> 0 | ... P22: ='📋 Job 3'!P13 -> 0
A23: Total Outflows | C23: =SUM('📋 Job 3'!D24:P24) -> 0 | D23: ='📋 Job 3'!D24 -> 0 | E23: ='📋 Job 3'!E24 -> 0 | F23: ='📋 Job 3'!F24 -> 0 | G23: ='📋 Job 3'!G24 -> 0 | H23: ='📋 Job 3'!H24 -> 0 | I23: ='📋 Job 3'!I24 -> 0 | J23: ='📋 Job 3'!J24 -> 0 | K23: ='📋 Job 3'!K24 -> 0 | ... P23: ='📋 Job 3'!P24 -> 0
A24: Net Cash Flow | C24: =SUM('📋 Job 3'!D26:P26) -> 0 | D24: ='📋 Job 3'!D26 -> 0 | E24: ='📋 Job 3'!E26 -> 0 | F24: ='📋 Job 3'!F26 -> 0 | G24: ='📋 Job 3'!G26 -> 0 | H24: ='📋 Job 3'!H26 -> 0 | I24: ='📋 Job 3'!I26 -> 0 | J24: ='📋 Job 3'!J26 -> 0 | K24: ='📋 Job 3'!K26 -> 0 | ... P24: ='📋 Job 3'!P26 -> 0
A25: Ending Cash Balance | C25: ='📋 Job 3'!P27 -> 0 | D25: ='📋 Job 3'!D27 -> 0 | E25: ='📋 Job 3'!E27 -> 0 | F25: ='📋 Job 3'!F27 -> 0 | G25: ='📋 Job 3'!G27 -> 0 | H25: ='📋 Job 3'!H27 -> 0 | I25: ='📋 Job 3'!I27 -> 0 | J25: ='📋 Job 3'!J27 -> 0 | K25: ='📋 Job 3'!K27 -> 0 | ... P25: ='📋 Job 3'!P27 -> 0
A27: Job 4
A28: Total Inflows | C28: =SUM('📋 Job 4'!D13:P13) -> 0 | D28: ='📋 Job 4'!D13 -> 0 | E28: ='📋 Job 4'!E13 -> 0 | F28: ='📋 Job 4'!F13 -> 0 | G28: ='📋 Job 4'!G13 -> 0 | H28: ='📋 Job 4'!H13 -> 0 | I28: ='📋 Job 4'!I13 -> 0 | J28: ='📋 Job 4'!J13 -> 0 | K28: ='📋 Job 4'!K13 -> 0 | ... P28: ='📋 Job 4'!P13 -> 0
A29: Total Outflows | C29: =SUM('📋 Job 4'!D24:P24) -> 0 | D29: ='📋 Job 4'!D24 -> 0 | E29: ='📋 Job 4'!E24 -> 0 | F29: ='📋 Job 4'!F24 -> 0 | G29: ='📋 Job 4'!G24 -> 0 | H29: ='📋 Job 4'!H24 -> 0 | I29: ='📋 Job 4'!I24 -> 0 | J29: ='📋 Job 4'!J24 -> 0 | K29: ='📋 Job 4'!K24 -> 0 | ... P29: ='📋 Job 4'!P24 -> 0
A30: Net Cash Flow | C30: =SUM('📋 Job 4'!D26:P26) -> 0 | D30: ='📋 Job 4'!D26 -> 0 | E30: ='📋 Job 4'!E26 -> 0 | F30: ='📋 Job 4'!F26 -> 0 | G30: ='📋 Job 4'!G26 -> 0 | H30: ='📋 Job 4'!H26 -> 0 | I30: ='📋 Job 4'!I26 -> 0 | J30: ='📋 Job 4'!J26 -> 0 | K30: ='📋 Job 4'!K26 -> 0 | ... P30: ='📋 Job 4'!P26 -> 0
A31: Ending Cash Balance | C31: ='📋 Job 4'!P27 -> 0 | D31: ='📋 Job 4'!D27 -> 0 | E31: ='📋 Job 4'!E27 -> 0 | F31: ='📋 Job 4'!F27 -> 0 | G31: ='📋 Job 4'!G27 -> 0 | H31: ='📋 Job 4'!H27 -> 0 | I31: ='📋 Job 4'!I27 -> 0 | J31: ='📋 Job 4'!J27 -> 0 | K31: ='📋 Job 4'!K27 -> 0 | ... P31: ='📋 Job 4'!P27 -> 0
A33: Job 5
A34: Total Inflows | C34: =SUM('📋 Job 5'!D13:P13) -> 0 | D34: ='📋 Job 5'!D13 -> 0 | E34: ='📋 Job 5'!E13 -> 0 | F34: ='📋 Job 5'!F13 -> 0 | G34: ='📋 Job 5'!G13 -> 0 | H34: ='📋 Job 5'!H13 -> 0 | I34: ='📋 Job 5'!I13 -> 0 | J34: ='📋 Job 5'!J13 -> 0 | K34: ='📋 Job 5'!K13 -> 0 | ... P34: ='📋 Job 5'!P13 -> 0
A35: Total Outflows | C35: =SUM('📋 Job 5'!D24:P24) -> 0 | D35: ='📋 Job 5'!D24 -> 0 | E35: ='📋 Job 5'!E24 -> 0 | F35: ='📋 Job 5'!F24 -> 0 | G35: ='📋 Job 5'!G24 -> 0 | H35: ='📋 Job 5'!H24 -> 0 | I35: ='📋 Job 5'!I24 -> 0 | J35: ='📋 Job 5'!J24 -> 0 | K35: ='📋 Job 5'!K24 -> 0 | ... P35: ='📋 Job 5'!P24 -> 0
A36: Net Cash Flow | C36: =SUM('📋 Job 5'!D26:P26) -> 0 | D36: ='📋 Job 5'!D26 -> 0 | E36: ='📋 Job 5'!E26 -> 0 | F36: ='📋 Job 5'!F26 -> 0 | G36: ='📋 Job 5'!G26 -> 0 | H36: ='📋 Job 5'!H26 -> 0 | I36: ='📋 Job 5'!I26 -> 0 | J36: ='📋 Job 5'!J26 -> 0 | K36: ='📋 Job 5'!K26 -> 0 | ... P36: ='📋 Job 5'!P26 -> 0
A37: Ending Cash Balance | C37: ='📋 Job 5'!P27 -> 0 | D37: ='📋 Job 5'!D27 -> 0 | E37: ='📋 Job 5'!E27 -> 0 | F37: ='📋 Job 5'!F27 -> 0 | G37: ='📋 Job 5'!G27 -> 0 | H37: ='📋 Job 5'!H27 -> 0 | I37: ='📋 Job 5'!I27 -> 0 | J37: ='📋 Job 5'!J27 -> 0 | K37: ='📋 Job 5'!K27 -> 0 | ... P37: ='📋 Job 5'!P27 -> 0
A39: ▼ COMPANY-WIDE TOTALS
A40: Total Inflows — All Jobs | C40: =SUM('📋 Job 1'!D13:P13)+SUM('📋 Job 2'!D13:P13)+SUM('📋 Job 3'!D13:P13)+SUM('📋 Job 4'!D13:P13)+SUM('📋 Job 5'!D13:P13) -> 0 | D40: ='📋 Job 1'!D13+'📋 Job 2'!D13+'📋 Job 3'!D13+'📋 Job 4'!D13+'📋 Job 5'!D13 -> 0 | E40: ='📋 Job 1'!E13+'📋 Job 2'!E13+'📋 Job 3'!E13+'📋 Job 4'!E13+'📋 Job 5'!E13 -> 0 | F40: ='📋 Job 1'!F13+'📋 Job 2'!F13+'📋 Job 3'!F13+'📋 Job 4'!F13+'📋 Job 5'!F13 -> 0 | G40: ='📋 Job 1'!G13+'📋 Job 2'!G13+'📋 Job 3'!G13+'📋 Job 4'!G13+'📋 Job 5'!G13 -> 0 | H40: ='📋 Job 1'!H13+'📋 Job 2'!H13+'📋 Job 3'!H13+'📋 Job 4'!H13+'📋 Job 5'!H13 -> 0 | I40: ='📋 Job 1'!I13+'📋 Job 2'!I13+'📋 Job 3'!I13+'📋 Job 4'!I13+'📋 Job 5'!I13 -> 0 | J40: ='📋 Job 1'!J13+'📋 Job 2'!J13+'📋 Job 3'!J13+'📋 Job 4'!J13+'📋 Job 5'!J13 -> 0 | K40: ='📋 Job 1'!K13+'📋 Job 2'!K13+'📋 Job 3'!K13+'📋 Job 4'!K13+'📋 Job 5'!K13 -> 0 | ... P40: ='📋 Job 1'!P13+'📋 Job 2'!P13+'📋 Job 3'!P13+'📋 Job 4'!P13+'📋 Job 5'!P13 -> 0
A41: Total Outflows — All Jobs | C41: =SUM('📋 Job 1'!D24:P24)+SUM('📋 Job 2'!D24:P24)+SUM('📋 Job 3'!D24:P24)+SUM('📋 Job 4'!D24:P24)+SUM('📋 Job 5'!D24:P24) -> 0 | D41: ='📋 Job 1'!D24+'📋 Job 2'!D24+'📋 Job 3'!D24+'📋 Job 4'!D24+'📋 Job 5'!D24 -> 0 | E41: ='📋 Job 1'!E24+'📋 Job 2'!E24+'📋 Job 3'!E24+'📋 Job 4'!E24+'📋 Job 5'!E24 -> 0 | F41: ='📋 Job 1'!F24+'📋 Job 2'!F24+'📋 Job 3'!F24+'📋 Job 4'!F24+'📋 Job 5'!F24 -> 0 | G41: ='📋 Job 1'!G24+'📋 Job 2'!G24+'📋 Job 3'!G24+'📋 Job 4'!G24+'📋 Job 5'!G24 -> 0 | H41: ='📋 Job 1'!H24+'📋 Job 2'!H24+'📋 Job 3'!H24+'📋 Job 4'!H24+'📋 Job 5'!H24 -> 0 | I41: ='📋 Job 1'!I24+'📋 Job 2'!I24+'📋 Job 3'!I24+'📋 Job 4'!I24+'📋 Job 5'!I24 -> 0 | J41: ='📋 Job 1'!J24+'📋 Job 2'!J24+'📋 Job 3'!J24+'📋 Job 4'!J24+'📋 Job 5'!J24 -> 0 | K41: ='📋 Job 1'!K24+'📋 Job 2'!K24+'📋 Job 3'!K24+'📋 Job 4'!K24+'📋 Job 5'!K24 -> 0 | ... P41: ='📋 Job 1'!P24+'📋 Job 2'!P24+'📋 Job 3'!P24+'📋 Job 4'!P24+'📋 Job 5'!P24 -> 0
A42: Net Cash Flow — All Jobs | C42: =SUM('📋 Job 1'!D26:P26)+SUM('📋 Job 2'!D26:P26)+SUM('📋 Job 3'!D26:P26)+SUM('📋 Job 4'!D26:P26)+SUM('📋 Job 5'!D26:P26) -> 0 | D42: ='📋 Job 1'!D26+'📋 Job 2'!D26+'📋 Job 3'!D26+'📋 Job 4'!D26+'📋 Job 5'!D26 -> 0 | E42: ='📋 Job 1'!E26+'📋 Job 2'!E26+'📋 Job 3'!E26+'📋 Job 4'!E26+'📋 Job 5'!E26 -> 0 | F42: ='📋 Job 1'!F26+'📋 Job 2'!F26+'📋 Job 3'!F26+'📋 Job 4'!F26+'📋 Job 5'!F26 -> 0 | G42: ='📋 Job 1'!G26+'📋 Job 2'!G26+'📋 Job 3'!G26+'📋 Job 4'!G26+'📋 Job 5'!G26 -> 0 | H42: ='📋 Job 1'!H26+'📋 Job 2'!H26+'📋 Job 3'!H26+'📋 Job 4'!H26+'📋 Job 5'!H26 -> 0 | I42: ='📋 Job 1'!I26+'📋 Job 2'!I26+'📋 Job 3'!I26+'📋 Job 4'!I26+'📋 Job 5'!I26 -> 0 | J42: ='📋 Job 1'!J26+'📋 Job 2'!J26+'📋 Job 3'!J26+'📋 Job 4'!J26+'📋 Job 5'!J26 -> 0 | K42: ='📋 Job 1'!K26+'📋 Job 2'!K26+'📋 Job 3'!K26+'📋 Job 4'!K26+'📋 Job 5'!K26 -> 0 | ... P42: ='📋 Job 1'!P26+'📋 Job 2'!P26+'📋 Job 3'!P26+'📋 Job 4'!P26+'📋 Job 5'!P26 -> 0
A43: Combined Ending Cash Balance | C43: ='📋 Job 1'!P27+'📋 Job 2'!P27+'📋 Job 3'!P27+'📋 Job 4'!P27+'📋 Job 5'!P27 -> 0 | D43: ='📋 Job 1'!D27+'📋 Job 2'!D27+'📋 Job 3'!D27+'📋 Job 4'!D27+'📋 Job 5'!D27 -> 0 | E43: ='📋 Job 1'!E27+'📋 Job 2'!E27+'📋 Job 3'!E27+'📋 Job 4'!E27+'📋 Job 5'!E27 -> 0 | F43: ='📋 Job 1'!F27+'📋 Job 2'!F27+'📋 Job 3'!F27+'📋 Job 4'!F27+'📋 Job 5'!F27 -> 0 | G43: ='📋 Job 1'!G27+'📋 Job 2'!G27+'📋 Job 3'!G27+'📋 Job 4'!G27+'📋 Job 5'!G27 -> 0 | H43: ='📋 Job 1'!H27+'📋 Job 2'!H27+'📋 Job 3'!H27+'📋 Job 4'!H27+'📋 Job 5'!H27 -> 0 | I43: ='📋 Job 1'!I27+'📋 Job 2'!I27+'📋 Job 3'!I27+'📋 Job 4'!I27+'📋 Job 5'!I27 -> 0 | J43: ='📋 Job 1'!J27+'📋 Job 2'!J27+'📋 Job 3'!J27+'📋 Job 4'!J27+'📋 Job 5'!J27 -> 0 | K43: ='📋 Job 1'!K27+'📋 Job 2'!K27+'📋 Job 3'!K27+'📋 Job 4'!K27+'📋 Job 5'!K27 -> 0 | ... P43: ='📋 Job 1'!P27+'📋 Job 2'!P27+'📋 Job 3'!P27+'📋 Job 4'!P27+'📋 Job 5'!P27 -> 0
A45: COMBINED ENDING CASH COLOR GUIDE: 🔴 Red = Below Company Red Zone 🟠 Orange = Within 20% above threshold 🟢 Green = Healthy
A47: COMPANY CASH HEALTH SNAPSHOT
A48: Total 13-Week Inflows (All Jobs) | E48: =SUM('📋 Job 1'!D13:P13)+SUM('📋 Job 2'!D13:P13)+SUM('📋 Job 3'!D13:P13)+SUM('📋 Job 4'!D13:P13)+SUM('📋 Job 5'!D13:P13) -> 0
A49: Total 13-Week Outflows (All Jobs) | E49: =SUM('📋 Job 1'!D24:P24)+SUM('📋 Job 2'!D24:P24)+SUM('📋 Job 3'!D24:P24)+SUM('📋 Job 4'!D24:P24)+SUM('📋 Job 5'!D24:P24) -> 0
...

Sheet 📋 Job 1
A1: CASH FLOW OFFICE | 13-Week Cash Flow Planner — Job 1
A2: Job / Project: | D2: Client: | G2: Project Manager: | J2: Report Date:
A3: Opening Cash Balance: | B3: 0 | E3: 🔴 Red Zone Threshold: | F3: 5000 | G3: ← Enter the minimum cash balance you want to maintain at all times. Weeks falling below this trigger a red alert.
A5: CATEGORY | C5: NOTES / ANNUAL | D5: WEEK 1 | E5: WEEK 2 | F5: WEEK 3 | G5: WEEK 4 | H5: WEEK 5 | I5: WEEK 6 | J5: WEEK 7 | K5: WEEK 8 | L5: WEEK 9 | M5: WEEK 10 | N5: WEEK 11 | O5: WEEK 12 | P5: WEEK 13
A6: Week Starting Date →
A8: ▼ CASH INFLOWS
A9: Draw Requests / Progress Billings | C9: Expected draw receipts from owner/GC this week
A10: Retainage Releases | C10: Retainage dollars expected to be released/paid this week
A11: Customer Deposits | C11: Upfront deposits or milestone deposits from clients
A12: Other Income | C12: Any other cash inflows (insurance proceeds, reimbursements, etc.)
A13: TOTAL INFLOWS | D13: =SUM(D9:D12) -> 0 | E13: =SUM(E9:E12) -> 0 | F13: =SUM(F9:F12) -> 0 | G13: =SUM(G9:G12) -> 0 | H13: =SUM(H9:H12) -> 0 | I13: =SUM(I9:I12) -> 0 | J13: =SUM(J9:J12) -> 0 | K13: =SUM(K9:K12) -> 0 | ... P13: =SUM(P9:P12) -> 0
A15: ▼ CASH OUTFLOWS
A16: Payroll / Labor | C16: Gross payroll including owner salary if paid through payroll
A17: Subcontractor Payments | C17: Payments to subs — note: pay-when-paid clauses may shift timing
A18: Material Purchases | C18: Lumber, concrete, MEP materials, finishes, etc.
A19: Equipment Rental | C19: Crane, excavator, lift, scaffolding, tool rentals
A20: Overhead (Rent, Insurance, Utilities, Admin) | C20: Fixed overhead — same each week. Enter monthly ÷ 4.33 for weekly
A21: Loan / Line of Credit Payments | C21: Scheduled debt service or LOC draws/repayments
A22: Owner Draw / Distributions | C22: Cash taken out by owner(s) — critical to track for cash planning
A23: Other Outflows | C23: Permits, fees, unexpected costs, tax payments, etc.
A24: TOTAL OUTFLOWS | D24: =SUM(D16:D23) -> 0 | E24: =SUM(E16:E23) -> 0 | F24: =SUM(F16:F23) -> 0 | G24: =SUM(G16:G23) -> 0 | H24: =SUM(H16:H23) -> 0 | I24: =SUM(I16:I23) -> 0 | J24: =SUM(J16:J23) -> 0 | K24: =SUM(K16:K23) -> 0 | ... P24: =SUM(P16:P23) -> 0
A26: NET CASH FLOW | D26: =D13-D24 -> 0 | E26: =E13-E24 -> 0 | F26: =F13-F24 -> 0 | G26: =G13-G24 -> 0 | H26: =H13-H24 -> 0 | I26: =I13-I24 -> 0 | J26: =J13-J24 -> 0 | K26: =K13-K24 -> 0 | ... P26: =P13-P24 -> 0
A27: ENDING CASH BALANCE | D27: =B3+D26 -> 0 | E27: =D27+E26 -> 0 | F27: =E27+F26 -> 0 | G27: =F27+G26 -> 0 | H27: =G27+H26 -> 0 | I27: =H27+I26 -> 0 | J27: =I27+J26 -> 0 | K27: =J27+K26 -> 0 | L27: =K27+L26 -> 0 | ... P27: =O27+P26 -> 0
A28: ENDING CASH COLOR GUIDE: 🔴 Red = Below Red Zone threshold (danger) 🟠 Orange = Within 20% above threshold (warning) 🟢 Green = Healthy (≥ 120% of threshold)
A30: 13-WEEK SUMMARY
A31: Opening Cash Balance | E31: =B3 -> 0
A32: Total 13-Week Inflows | E32: =SUM(D13:P13) -> 0
A33: Total 13-Week Outflows | E33: =SUM(D24:P24) -> 0
A34: Net Cash Flow (13 Weeks) | E34: =SUM(D26:P26) -> 0
A35: Closing Cash (End of Week 13) | E35: =P27 -> 0
A36: Lowest Ending Cash (Any Week) | E36: =MIN(D27:P27) -> 0
A37: Highest Ending Cash (Any Week) | E37: =MAX(D27:P27) -> 0
A38: Weeks Below Red Zone Threshold | E38: =COUNTIF(D27:P27,"<"&F3) -> 13
A39: Total Draw Requests Expected | E39: =SUM(D9:P9) -> 0
A40: Total Retainage Expected | E40: =SUM(D10:P10) -> 0
A41: Total Payroll (13 Weeks) | E41: =SUM(D16:P16) -> 0
A42: Total Sub Payments (13 Weeks) | E42: =SUM(D17:P17) -> 0
A44: Cash Flow Office | cfo@cashflowoffice.com | cashflowoffice.com | © 2026 Darlene Martin | Unprotect password: CFO2026

Sheet 📋 Job 2
A1: CASH FLOW OFFICE | 13-Week Cash Flow Planner — Job 2
A2: Job / Project: | D2: Client: | G2: Project Manager: | J2: Report Date:
A3: Opening Cash Balance: | B3: 0 | E3: 🔴 Red Zone Threshold: | F3: 5000 | G3: ← Enter the minimum cash balance you want to maintain at all times. Weeks falling below this trigger a red alert.
A5: CATEGORY | C5: NOTES / ANNUAL | D5: WEEK 1 | E5: WEEK 2 | F5: WEEK 3 | G5: WEEK 4 | H5: WEEK 5 | I5: WEEK 6 | J5: WEEK 7 | K5: WEEK 8 | L5: WEEK 9 | M5: WEEK 10 | N5: WEEK 11 | O5: WEEK 12 | P5: WEEK 13
A6: Week Starting Date →
A8: ▼ CASH INFLOWS
A9: Draw Requests / Progress Billings | C9: Expected draw receipts from owner/GC this week
A10: Retainage Releases | C10: Retainage dollars expected to be released/paid this week
A11: Customer Deposits | C11: Upfront deposits or milestone deposits from clients
A12: Other Income | C12: Any other cash inflows (insurance proceeds, reimbursements, etc.)
A13: TOTAL INFLOWS | D13: =SUM(D9:D12) -> 0 | E13: =SUM(E9:E12) -> 0 | F13: =SUM(F9:F12) -> 0 | G13: =SUM(G9:G12) -> 0 | H13: =SUM(H9:H12) -> 0 | I13: =SUM(I9:I12) -> 0 | J13: =SUM(J9:J12) -> 0 | K13: =SUM(K9:K12) -> 0 | ... P13: =SUM(P9:P12) -> 0
A15: ▼ CASH OUTFLOWS
A16: Payroll / Labor | C16: Gross payroll including owner salary if paid through payroll
A17: Subcontractor Payments | C17: Payments to subs — note: pay-when-paid clauses may shift timing
A18: Material Purchases | C18: Lumber, concrete, MEP materials, finishes, etc.
A19: Equipment Rental | C19: Crane, excavator, lift, scaffolding, tool rentals
A20: Overhead (Rent, Insurance, Utilities, Admin) | C20: Fixed overhead — same each week. Enter monthly ÷ 4.33 for weekly
A21: Loan / Line of Credit Payments | C21: Scheduled debt service or LOC draws/repayments
A22: Owner Draw / Distributions | C22: Cash taken out by owner(s) — critical to track for cash planning
A23: Other Outflows | C23: Permits, fees, unexpected costs, tax payments, etc.
A24: TOTAL OUTFLOWS | D24: =SUM(D16:D23) -> 0 | E24: =SUM(E16:E23) -> 0 | F24: =SUM(F16:F23) -> 0 | G24: =SUM(G16:G23) -> 0 | H24: =SUM(H16:H23) -> 0 | I24: =SUM(I16:I23) -> 0 | J24: =SUM(J16:J23) -> 0 | K24: =SUM(K16:K23) -> 0 | ... P24: =SUM(P16:P23) -> 0
A26: NET CASH FLOW | D26: =D13-D24 -> 0 | E26: =E13-E24 -> 0 | F26: =F13-F24 -> 0 | G26: =G13-G24 -> 0 | H26: =H13-H24 -> 0 | I26: =I13-I24 -> 0 | J26: =J13-J24 -> 0 | K26: =K13-K24 -> 0 | ... P26: =P13-P24 -> 0
A27: ENDING CASH BALANCE | D27: =B3+D26 -> 0 | E27: =D27+E26 -> 0 | F27: =E27+F26 -> 0 | G27: =F27+G26 -> 0 | H27: =G27+H26 -> 0 | I27: =H27+I26 -> 0 | J27: =I27+J26 -> 0 | K27: =J27+K26 -> 0 | L27: =K27+L26 -> 0 | ... P27: =O27+P26 -> 0
A28: ENDING CASH COLOR GUIDE: 🔴 Red = Below Red Zone threshold (danger) 🟠 Orange = Within 20% above threshold (warning) 🟢 Green = Healthy (≥ 120% of threshold)
A30: 13-WEEK SUMMARY
A31: Opening Cash Balance | E31: =B3 -> 0
A32: Total 13-Week Inflows | E32: =SUM(D13:P13) -> 0
A33: Total 13-Week Outflows | E33: =SUM(D24:P24) -> 0
A34: Net Cash Flow (13 Weeks) | E34: =SUM(D26:P26) -> 0
A35: Closing Cash (End of Week 13) | E35: =P27 -> 0
A36: Lowest Ending Cash (Any Week) | E36: =MIN(D27:P27) -> 0
A37: Highest Ending Cash (Any Week) | E37: =MAX(D27:P27) -> 0
A38: Weeks Below Red Zone Threshold | E38: =COUNTIF(D27:P27,"<"&F3) -> 13
A39: Total Draw Requests Expected | E39: =SUM(D9:P9) -> 0
A40: Total Retainage Expected | E40: =SUM(D10:P10) -> 0
A41: Total Payroll (13 Weeks) | E41: =SUM(D16:P16) -> 0
A42: Total Sub Payments (13 Weeks) | E42: =SUM(D17:P17) -> 0
A44: Cash Flow Office | cfo@cashflowoffice.com | cashflowoffice.com | © 2026 Darlene Martin | Unprotect password: CFO2026

Sheet 📋 Job 3
A1: CASH FLOW OFFICE | 13-Week Cash Flow Planner — Job 3
A2: Job / Project: | D2: Client: | G2: Project Manager: | J2: Report Date:
A3: Opening Cash Balance: | B3: 0 | E3: 🔴 Red Zone Threshold: | F3: 5000 | G3: ← Enter the minimum cash balance you want to maintain at all times. Weeks falling below this trigger a red alert.
A5: CATEGORY | C5: NOTES / ANNUAL | D5: WEEK 1 | E5: WEEK 2 | F5: WEEK 3 | G5: WEEK 4 | H5: WEEK 5 | I5: WEEK 6 | J5: WEEK 7 | K5: WEEK 8 | L5: WEEK 9 | M5: WEEK 10 | N5: WEEK 11 | O5: WEEK 12 | P5: WEEK 13
A6: Week Starting Date →
A8: ▼ CASH INFLOWS
A9: Draw Requests / Progress Billings | C9: Expected draw receipts from owner/GC this week
A10: Retainage Releases | C10: Retainage dollars expected to be released/paid this week
A11: Customer Deposits | C11: Upfront deposits or milestone deposits from clients
A12: Other Income | C12: Any other cash inflows (insurance proceeds, reimbursements, etc.)
A13: TOTAL INFLOWS | D13: =SUM(D9:D12) -> 0 | E13: =SUM(E9:E12) -> 0 | F13: =SUM(F9:F12) -> 0 | G13: =SUM(G9:G12) -> 0 | H13: =SUM(H9:H12) -> 0 | I13: =SUM(I9:I12) -> 0 | J13: =SUM(J9:J12) -> 0 | K13: =SUM(K9:K12) -> 0 | ... P13: =SUM(P9:P12) -> 0
A15: ▼ CASH OUTFLOWS
A16: Payroll / Labor | C16: Gross payroll including owner salary if paid through payroll
A17: Subcontractor Payments | C17: Payments to subs — note: pay-when-paid clauses may shift timing
A18: Material Purchases | C18: Lumber, concrete, MEP materials, finishes, etc.
A19: Equipment Rental | C19: Crane, excavator, lift, scaffolding, tool rentals
A20: Overhead (Rent, Insurance, Utilities, Admin) | C20: Fixed overhead — same each week. Enter monthly ÷ 4.33 for weekly
A21: Loan / Line of Credit Payments | C21: Scheduled debt service or LOC draws/repayments
A22: Owner Draw / Distributions | C22: Cash taken out by owner(s) — critical to track for cash planning
A23: Other Outflows | C23: Permits, fees, unexpected costs, tax payments, etc.
A24: TOTAL OUTFLOWS | D24: =SUM(D16:D23) -> 0 | E24: =SUM(E16:E23) -> 0 | F24: =SUM(F16:F23) -> 0 | G24: =SUM(G16:G23) -> 0 | H24: =SUM(H16:H23) -> 0 | I24: =SUM(I16:I23) -> 0 | J24: =SUM(J16:J23) -> 0 | K24: =SUM(K16:K23) -> 0 | ... P24: =SUM(P16:P23) -> 0
A26: NET CASH FLOW | D26: =D13-D24 -> 0 | E26: =E13-E24 -> 0 | F26: =F13-F24 -> 0 | G26: =G13-G24 -> 0 | H26: =H13-H24 -> 0 | I26: =I13-I24 -> 0 | J26: =J13-J24 -> 0 | K26: =K13-K24 -> 0 | ... P26: =P13-P24 -> 0
A27: ENDING CASH BALANCE | D27: =B3+D26 -> 0 | E27: =D27+E26 -> 0 | F27: =E27+F26 -> 0 | G27: =F27+G26 -> 0 | H27: =G27+H26 -> 0 | I27: =H27+I26 -> 0 | J27: =I27+J26 -> 0 | K27: =J27+K26 -> 0 | L27: =K27+L26 -> 0 | ... P27: =O27+P26 -> 0
A28: ENDING CASH COLOR GUIDE: 🔴 Red = Below Red Zone threshold (danger) 🟠 Orange = Within 20% above threshold (warning) 🟢 Green = Healthy (≥ 120% of threshold)
A30: 13-WEEK SUMMARY
A31: Opening Cash Balance | E31: =B3 -> 0
A32: Total 13-Week Inflows | E32: =SUM(D13:P13) -> 0
A33: Total 13-Week Outflows | E33: =SUM(D24:P24) -> 0
A34: Net Cash Flow (13 Weeks) | E34: =SUM(D26:P26) -> 0
A35: Closing Cash (End of Week 13) | E35: =P27 -> 0
A36: Lowest Ending Cash (Any Week) | E36: =MIN(D27:P27) -> 0
A37: Highest Ending Cash (Any Week) | E37: =MAX(D27:P27) -> 0
A38: Weeks Below Red Zone Threshold | E38: =COUNTIF(D27:P27,"<"&F3) -> 13
A39: Total Draw Requests Expected | E39: =SUM(D9:P9) -> 0
A40: Total Retainage Expected | E40: =SUM(D10:P10) -> 0
A41: Total Payroll (13 Weeks) | E41: =SUM(D16:P16) -> 0
A42: Total Sub Payments (13 Weeks) | E42: =SUM(D17:P17) -> 0
A44: Cash Flow Office | cfo@cashflowoffice.com | cashflowoffice.com | © 2026 Darlene Martin | Unprotect password: CFO2026

Sheet 📋 Job 4
A1: CASH FLOW OFFICE | 13-Week Cash Flow Planner — Job 4
A2: Job / Project: | D2: Client: | G2: Project Manager: | J2: Report Date:
A3: Opening Cash Balance: | B3: 0 | E3: 🔴 Red Zone Threshold: | F3: 5000 | G3: ← Enter the minimum cash balance you want to maintain at all times. Weeks falling below this trigger a red alert.
A5: CATEGORY | C5: NOTES / ANNUAL | D5: WEEK 1 | E5: WEEK 2 | F5: WEEK 3 | G5: WEEK 4 | H5: WEEK 5 | I5: WEEK 6 | J5: WEEK 7 | K5: WEEK 8 | L5: WEEK 9 | M5: WEEK 10 | N5: WEEK 11 | O5: WEEK 12 | P5: WEEK 13
A6: Week Starting Date →
A8: ▼ CASH INFLOWS
A9: Draw Requests / Progress Billings | C9: Expected draw receipts from owner/GC this week
A10: Retainage Releases | C10: Retainage dollars expected to be released/paid this week
A11: Customer Deposits | C11: Upfront deposits or milestone deposits from clients
A12: Other Income | C12: Any other cash inflows (insurance proceeds, reimbursements, etc.)
A13: TOTAL INFLOWS | D13: =SUM(D9:D12) -> 0 | E13: =SUM(E9:E12) -> 0 | F13: =SUM(F9:F12) -> 0 | G13: =SUM(G9:G12) -> 0 | H13: =SUM(H9:H12) -> 0 | I13: =SUM(I9:I12) -> 0 | J13: =SUM(J9:J12) -> 0 | K13: =SUM(K9:K12) -> 0 | ... P13: =SUM(P9:P12) -> 0
A15: ▼ CASH OUTFLOWS
A16: Payroll / Labor | C16: Gross payroll including owner salary if paid through payroll
A17: Subcontractor Payments | C17: Payments to subs — note: pay-when-paid clauses may shift timing
A18: Material Purchases | C18: Lumber, concrete, MEP materials, finishes, etc.
A19: Equipment Rental | C19: Crane, excavator, lift, scaffolding, tool rentals
A20: Overhead (Rent, Insurance, Utilities, Admin) | C20: Fixed overhead — same each week. Enter monthly ÷ 4.33 for weekly
A21: Loan / Line of Credit Payments | C21: Scheduled debt service or LOC draws/repayments
A22: Owner Draw / Distributions | C22: Cash taken out by owner(s) — critical to track for cash planning
A23: Other Outflows | C23: Permits, fees, unexpected costs, tax payments, etc.
A24: TOTAL OUTFLOWS | D24: =SUM(D16:D23) -> 0 | E24: =SUM(E16:E23) -> 0 | F24: =SUM(F16:F23) -> 0 | G24: =SUM(G16:G23) -> 0 | H24: =SUM(H16:H23) -> 0 | I24: =SUM(I16:I23) -> 0 | J24: =SUM(J16:J23) -> 0 | K24: =SUM(K16:K23) -> 0 | ... P24: =SUM(P16:P23) -> 0
A26: NET CASH FLOW | D26: =D13-D24 -> 0 | E26: =E13-E24 -> 0 | F26: =F13-F24 -> 0 | G26: =G13-G24 -> 0 | H26: =H13-H24 -> 0 | I26: =I13-I24 -> 0 | J26: =J13-J24 -> 0 | K26: =K13-K24 -> 0 | ... P26: =P13-P24 -> 0
A27: ENDING CASH BALANCE | D27: =B3+D26 -> 0 | E27: =D27+E26 -> 0 | F27: =E27+F26 -> 0 | G27: =F27+G26 -> 0 | H27: =G27+H26 -> 0 | I27: =H27+I26 -> 0 | J27: =I27+J26 -> 0 | K27: =J27+K26 -> 0 | L27: =K27+L26 -> 0 | ... P27: =O27+P26 -> 0
A28: ENDING CASH COLOR GUIDE: 🔴 Red = Below Red Zone threshold (danger) 🟠 Orange = Within 20% above threshold (warning) 🟢 Green = Healthy (≥ 120% of threshold)
A30: 13-WEEK SUMMARY
A31: Opening Cash Balance | E31: =B3 -> 0
A32: Total 13-Week Inflows | E32: =SUM(D13:P13) -> 0
A33: Total 13-Week Outflows | E33: =SUM(D24:P24) -> 0
A34: Net Cash Flow (13 Weeks) | E34: =SUM(D26:P26) -> 0
A35: Closing Cash (End of Week 13) | E35: =P27 -> 0
A36: Lowest Ending Cash (Any Week) | E36: =MIN(D27:P27) -> 0
A37: Highest Ending Cash (Any Week) | E37: =MAX(D27:P27) -> 0
A38: Weeks Below Red Zone Threshold | E38: =COUNTIF(D27:P27,"<"&F3) -> 13
A39: Total Draw Requests Expected | E39: =SUM(D9:P9) -> 0
A40: Total Retainage Expected | E40: =SUM(D10:P10) -> 0
A41: Total Payroll (13 Weeks) | E41: =SUM(D16:P16) -> 0
A42: Total Sub Payments (13 Weeks) | E42: =SUM(D17:P17) -> 0
A44: Cash Flow Office | cfo@cashflowoffice.com | cashflowoffice.com | © 2026 Darlene Martin | Unprotect password: CFO2026

Sheet 📋 Job 5
A1: CASH FLOW OFFICE | 13-Week Cash Flow Planner — Job 5
A2: Job / Project: | D2: Client: | G2: Project Manager: | J2: Report Date:
A3: Opening Cash Balance: | B3: 0 | E3: 🔴 Red Zone Threshold: | F3: 5000 | G3: ← Enter the minimum cash balance you want to maintain at all times. Weeks falling below this trigger a red alert.
A5: CATEGORY | C5: NOTES / ANNUAL | D5: WEEK 1 | E5: WEEK 2 | F5: WEEK 3 | G5: WEEK 4 | H5: WEEK 5 | I5: WEEK 6 | J5: WEEK 7 | K5: WEEK 8 | L5: WEEK 9 | M5: WEEK 10 | N5: WEEK 11 | O5: WEEK 12 | P5: WEEK 13
A6: Week Starting Date →
A8: ▼ CASH INFLOWS
A9: Draw Requests / Progress Billings | C9: Expected draw receipts from owner/GC this week
A10: Retainage Releases | C10: Retainage dollars expected to be released/paid this week
A11: Customer Deposits | C11: Upfront deposits or milestone deposits from clients
A12: Other Income | C12: Any other cash inflows (insurance proceeds, reimbursements, etc.)
A13: TOTAL INFLOWS | D13: =SUM(D9:D12) -> 0 | E13: =SUM(E9:E12) -> 0 | F13: =SUM(F9:F12) -> 0 | G13: =SUM(G9:G12) -> 0 | H13: =SUM(H9:H12) -> 0 | I13: =SUM(I9:I12) -> 0 | J13: =SUM(J9:J12) -> 0 | K13: =SUM(K9:K12) -> 0 | ... P13: =SUM(P9:P12) -> 0
A15: ▼ CASH OUTFLOWS
A16: Payroll / Labor | C16: Gross payroll including owner salary if paid through payroll
A17: Subcontractor Payments | C17: Payments to subs — note: pay-when-paid clauses may shift timing
A18: Material Purchases | C18: Lumber, concrete, MEP materials, finishes, etc.
A19: Equipment Rental | C19: Crane, excavator, lift, scaffolding, tool rentals
A20: Overhead (Rent, Insurance, Utilities, Admin) | C20: Fixed overhead — same each week. Enter monthly ÷ 4.33 for weekly
A21: Loan / Line of Credit Payments | C21: Scheduled debt service or LOC draws/repayments
A22: Owner Draw / Distributions | C22: Cash taken out by owner(s) — critical to track for cash planning
A23: Other Outflows | C23: Permits, fees, unexpected costs, tax payments, etc.
A24: TOTAL OUTFLOWS | D24: =SUM(D16:D23) -> 0 | E24: =SUM(E16:E23) -> 0 | F24: =SUM(F16:F23) -> 0 | G24: =SUM(G16:G23) -> 0 | H24: =SUM(H16:H23) -> 0 | I24: =SUM(I16:I23) -> 0 | J24: =SUM(J16:J23) -> 0 | K24: =SUM(K16:K23) -> 0 | ... P24: =SUM(P16:P23) -> 0
A26: NET CASH FLOW | D26: =D13-D24 -> 0 | E26: =E13-E24 -> 0 | F26: =F13-F24 -> 0 | G26: =G13-G24 -> 0 | H26: =H13-H24 -> 0 | I26: =I13-I24 -> 0 | J26: =J13-J24 -> 0 | K26: =K13-K24 -> 0 | ... P26: =P13-P24 -> 0
A27: ENDING CASH BALANCE | D27: =B3+D26 -> 0 | E27: =D27+E26 -> 0 | F27: =E27+F26 -> 0 | G27: =F27+G26 -> 0 | H27: =G27+H26 -> 0 | I27: =H27+I26 -> 0 | J27: =I27+J26 -> 0 | K27: =J27+K26 -> 0 | L27: =K27+L26 -> 0 | ... P27: =O27+P26 -> 0
A28: ENDING CASH COLOR GUIDE: 🔴 Red = Below Red Zone threshold (danger) 🟠 Orange = Within 20% above threshold (warning) 🟢 Green = Healthy (≥ 120% of threshold)
A30: 13-WEEK SUMMARY
A31: Opening Cash Balance | E31: =B3 -> 0
A32: Total 13-Week Inflows | E32: =SUM(D13:P13) -> 0
A33: Total 13-Week Outflows | E33: =SUM(D24:P24) -> 0
A34: Net Cash Flow (13 Weeks) | E34: =SUM(D26:P26) -> 0
A35: Closing Cash (End of Week 13) | E35: =P27 -> 0
A36: Lowest Ending Cash (Any Week) | E36: =MIN(D27:P27) -> 0
A37: Highest Ending Cash (Any Week) | E37: =MAX(D27:P27) -> 0
A38: Weeks Below Red Zone Threshold | E38: =COUNTIF(D27:P27,"<"&F3) -> 13
A39: Total Draw Requests Expected | E39: =SUM(D9:P9) -> 0
A40: Total Retainage Expected | E40: =SUM(D10:P10) -> 0
A41: Total Payroll (13 Weeks) | E41: =SUM(D16:P16) -> 0
A42: Total Sub Payments (13 Weeks) | E42: =SUM(D17:P17) -> 0
A44: Cash Flow Office | cfo@cashflowoffice.com | cashflowoffice.com | © 2026 Darlene Martin | Unprotect password: CFO2026

Sheet 📋 Instructions
A1: CASH FLOW OFFICE | 13-Week Cash Flow Planner — How to Use This Workbook
A3: This workbook has 7 tabs: Master Summary + 5 individual Job Cash Flow Planners + Instructions. Purpose: See exactly what cash is coming in and going out — week by week — for 13 weeks (90 days). This is a FORWARD-LOOKING decision tool. It answers: • Will I have enough cash to make payroll next week? • When will my next draw hit, and what do I need to pay before it does? • Which weeks are dangerous — and what can I do now to prevent a cash crisis?
A5: STEP 1 — SET UP EACH JOB TAB FIRST
B6: Name your Job tabs | C6: The 5 job tabs are pre-labeled Job 1–5. You can rename them in Excel by right-clicking the tab. Enter the job/project name, client, PM, and report date in the yellow header cells at the top.
B7: Enter Opening Cash Balance | C7: Row 3, left side. Enter the current cash balance for this job at the start of Week 1. This seeds the rolling ending cash calculation for all 13 weeks.
B8: Set your Red Zone Threshold | C8: Row 3, right side. Enter the minimum cash balance you want to maintain. This is your safety net — below this number, you're in danger. Typical contractors set this at 1–2 weeks of payroll. The ending cash row turns red automatically when you hit it.
A10: STEP 2 — ENTER WEEK START DATES
B11: Row 6 — date inputs | C11: Enter the Monday (or first day) of each week in row 6. These are input cells — enter Week 1's date and the Master Summary tab will pull dates from Job 1 automatically.
A13: STEP 3 — FILL IN INFLOWS AND OUTFLOWS WEEKLY
B14: INFLOWS (green section) | C14: Draw Requests / Progress Billings: Enter the EXPECTED RECEIPT date — not when you submitted the draw. Draws typically take 2–3 weeks from submission to cash in your account. Build in that lag. Retainage Releases: Only enter when you expect actual payment — not when it's theoretically owed. Customer Deposits: Upfront or milestone deposits. These are often your best early-week cash source.
B15: OUTFLOWS (red section) | C15: Payroll: Enter gross payroll. If bi-weekly, enter the full amount in the week it goes out. Subcontractor Payments: Note pay-when-paid clauses — subs typically get paid 30-45 days after GC pays you. Overhead: Fixed weekly amount. Tip: take monthly overhead ÷ 4.33 to get weekly figure. Owner Draw: Don't skip this — it's one of the most common causes of surprise cash shortages.
A17: STEP 4 — READ THE SIGNALS
B18: 🔴 Red ending cash week | C18: You are projected to fall below your safety threshold. Action needed NOW: Can you accelerate a draw request? Delay a material purchase? Push a sub payment one week? This is the whole point of the tool — catching this 4 weeks early.
B19: 🟠 Orange ending cash week | C19: Warning zone — within 20% above your threshold. Not a crisis yet but watch it closely. Review what's scheduled that week and the week after.
B20: 🟢 Green ending cash week | C20: Healthy — above 120% of your threshold. No immediate action needed.
A22: STEP 5 — USE THE MASTER SUMMARY TAB
B23: 📊 Master Summary tab | C23: Automatically consolidates all 5 job tabs. Shows inflows, outflows, net cash flow, and ending cash for each job side by side, week by week. Also shows company-wide combined ending cash with its own red zone threshold (set separately — typically higher than any single job threshold).
B24: Company Red Zone vs Job Red Zone | C24: Each job tab has its own threshold (what's safe for that job). The Master Summary has a separate company-level threshold (what's safe for the whole business). You might be fine on individual jobs but still be dangerously low company-wide — or vice versa. Check both.
A26: CONSTRUCTION-SPECIFIC TIPS
B27: Draw request lag | C27: The most common mistake: entering a draw in the week you SUBMIT it, not the week you RECEIVE it. In construction, draws take 14–21 days from submission to bank deposit. Always enter draws in the week the cash is expected to actually land.
B28: Pay-when-paid (subs) | C28: If your sub contracts include pay-when-paid clauses, your sub payment outflow shouldn't happen until AFTER you've received the corresponding draw. Model this correctly or your cash plan will show sub payments going out before inflows arrive — creating a false crisis on paper.
B29: Retainage timing | C29: Retainage is rarely released on time. If the contract says 30 days after substantial completion, budget 60–90 days in your planner. Conservative retainage timing is always safer than optimistic.
A31: COLOR & PROTECTION GUIDE
B32: 🟡 Yellow cells | C32: Input cells — enter your data here. Always unlocked.
B33: 🔵 Blue cells | C33: Formula cells — auto-calculated. Locked. Do not overwrite.
B34: 🔴 Red zone | C34: Ending cash below your threshold — cash danger, action required.
B35: 🟠 Orange zone | C35: Ending cash in warning range — monitor closely.
B36: 🟢 Green zone | C36: Ending cash healthy — above 120% of threshold.
B37: Unprotect | C37: Review → Unprotect Sheet → Password: CFO2026
A39: Cash Flow Office | cfo@cashflowoffice.com | cashflowoffice.com | © 2026 Darlene Martin | Unprotect password: CFO2026
